Workbook
Name Slicer_City: #N/A
Name Slicer_Department: #N/A
Name Slicer_Doctor_Assigned: #N/A
Name Timeline_Admission_Date: #N/A

Sheet RawData
A1: Patient_ID | B1: Patient_Name | C1: Age | D1: Gender | E1: Department | F1: City | G1: Admission_Date | H1: Discharge_Date | I1: Length_of_Stay | J1: Treatment_Cost | K1: Payment_Mode | L1: Insurance_Claimed | M1: Patient_Satisfaction | N1: Doctor_First_Name | O1: Doctor_Last_Name
A2: P0001 | B2: Patient_1 | C2: 39 | D2: F | E2: Pediatrics | F2: pune | G2: 44692 | H2: 44693 | I2: 1 | J2: 93509 | K2: Cash | L2: No | M2: 1 | N2: Dr. | O2: Khan
A3: P0002 | B3: Patient_2 | C3: 68 | D3: Male | E3: PEDIATRICS | F3: Bangalore | G3: 45333 | H3: 21-02-2024 | I3: 10 | J3: 14695 | K3: Card | L3: No | M3: 1 | N3: Dr. | O3: Desai
A4: P0003 | B4: Patient_3 | C4: 5 | D4: Female | E4: pediatrics | F4: Delhi | G4: 13-08-2022 | H4: 17-08-2022 | I4: 4 | J4: 98615 | K4: Cash | L4: No | M4: 5 | N4: Dr. | O4: Mehta
A5: P0004 | B5: Patient_4 | C5: 37 | D5: male | E5: neurology | F5: Hyderabad | G5: 45333 | H5: 16-02-2024 | I5: 5 | J5: 61048 | K5: UPI | L5: No | M5: 1 | N5: Dr. | O5: Sharma
A6: P0005 | B6: Patient_5 | C6: 48 | D6: male | E6: Cardiology | F6: DELHI | G6: 30-09-2023 | H6: 45201 | I6: 2 | J6: 52908 | K6: Insurance | L6: Yes | M6: 5 | N6: Dr. | O6: Mehta
A7: P0006 | B7: Patient_6 | C7: 40 | D7: M | E7: GENERAL MEDICINE | F7: delhi | G7: 45047 | H7: 45050 | I7: 3 | J7: 108187 | K7: Card | L7: Yes | M7: 4 | N7: Dr. | O7: Desai
A8: P0007 | B8: Patient_7 | C8: 24 | D8: F | E8: PEDIATRICS | F8: Bangalore | G8: 45174 | H8: 45179 | I8: 5 | J8: 116059 | K8: UPI | L8: No | M8: 5 | N8: Dr. | O8: Patil
A9: P0008 | B9: Patient_8 | C9: 13 | D9: m | E9: Pediatrics | F9: mumbai | G9: 22-02-2024 | H9: 45353 | I9: 9 | J9: 59036 | K9: Card | L9: No | M9: 5 | N9: Dr. | O9: Khan
A10: P0009 | B10: Patient_9 | C10: 53 | D10: male | E10: general medicine | F10: hyderabad | G10: 45172 | H10: 45180 | I10: 8 | J10: 82094 | K10: UPI | L10: No | M10: 4 | N10: Dr. | O10: Mehta
A11: P0010 | B11: Patient_10 | C11: 8 | D11: m | E11: Neurology | F11: Hyderabad | G11: 27-02-2022 | H11: 28-02-2022 | I11: 1 | J11: 27631 | K11: Insurance | L11: Yes | M11: 5 | N11: Dr. | O11: Patil
A12: P0001 | B12: Patient_11 | C12: 54 | D12: m | E12: Cardiology | F12: pune | G12: 44753 | H12: 20-07-2022 | I12: 9 | J12: 116839 | K12: Card | L12: No | M12: 2 | N12: Dr. | O12: Mehta
A13: P0002 | B13: Patient_12 | C13: 29 | D13: Female | E13: cardiology | F13: MUMBAI | G13: 25-05-2022 | H13: 44715 | I13: 9 | J13: 53775 | K13: Card | L13: Yes | M13: 3 | N13: Dr. | O13: Mehta
A14: P0003 | B14: Patient_13 | C14: 62 | D14: f | E14: Pediatrics | F14: BANGALORE | G14: 24-09-2022 | H14: 44838 | I14: 10 | J14: 145408 | K14: Insurance | L14: Yes | M14: 3 | N14: Dr. | O14: Desai
A15: P0004 | B15: Patient_14 | C15: 53 | D15: Male | E15: orthopedics | F15: Delhi | G15: 29-01-2023 | H15: 44962 | I15: 7 | J15: 141651 | K15: Card | L15: Yes | M15: 1 | N15: Dr. | O15: Patil
A16: P0005 | B16: Patient_15 | C16: 37 | D16: Male | E16: General Medicine | F16: hyderabad | G16: 44904 | H16: 15-12-2022 | I16: 6 | J16: 99486 | K16: Insurance | L16: No | M16: 3 | N16: Dr. | O16: Mehta
A17: P0006 | B17: Patient_16 | C17: 18 | D17: M | E17: neurology | F17: Hyderabad | G17: 29-04-2024 | H17: 45416 | I17: 5 | J17: 59428 | K17: Insurance | L17: No | M17: 2 | N17: Dr. | O17: Patil
A18: P0007 | B18: Patient_17 | C18: 22 | D18: m | E18: neurology | F18: Delhi | G18: 15-08-2023 | H18: 23-08-2023 | I18: 8 | J18: 109709 | K18: Cash | L18: No | M18: 1 | N18: Dr. | O18: Khan
A19: P0008 | B19: Patient_18 | C19: 68 | D19: female | E19: Cardiology | F19: delhi | G19: 31-10-2023 | H19: 45238 | I19: 8 | J19: 8680 | K19: Card | L19: No | M19: 3 | N19: Dr. | O19: Mehta
A20: P0009 | B20: Patient_19 | C20: 15 | D20: Male | E20: General Medicine | F20: Bangalore | G20: 18-01-2024 | H20: 27-01-2024 | I20: 9 | J20: 103785 | K20: Card | L20: Yes | M20: 5 | N20: Dr. | O20: Patil
A21: P0010 | B21: Patient_20 | C21: 45 | D21: Female | E21: Cardiology | F21: mumbai | G21: 44721 | H21: 44723 | I21: 2 | J21: 124363 | K21: Cash | L21: Yes | M21: 5 | N21: Dr. | O21: Desai
A22: P0021 | B22: Patient_21 | C22: 30 | D22: female | E22: cardiology | F22: pune | G22: 44783 | H22: 16-08-2022 | I22: 6 | J22: 60572 | K22: Insurance | L22: Yes | M22: 4 | N22: Dr. | O22: Mehta
A23: P0022 | B23: Patient_22 | C23: 48 | D23: Female | E23: general medicine | F23: BANGALORE | G23: 44990 | H23: 44995 | I23: 5 | J23: 40179 | K23: UPI | L23: No | M23: 1 | N23: Dr. | O23: Patil
A24: P0023 | B24: Patient_23 | C24: 61 | D24: m | E24: Neurology | F24: Mumbai | G24: 45333 | H24: 17-02-2024 | I24: 6 | J24: 95163 | K24: Insurance | L24: Yes | M24: 5 | N24: Dr. | O24: Mehta
A25: P0024 | B25: Patient_24 | C25: 9 | D25: f | E25: Cardiology | F25: Hyderabad | G25: 44814 | H25: 16-09-2022 | I25: 6 | J25: 37348 | K25: Card | L25: Yes | M25: 5 | N25: Dr. | O25: Desai
A26: P0025 | B26: Patient_25 | C26: 58 | D26: female | E26: General medicine | F26: DELHI | G26: 44906 | H26: 15-12-2022 | I26: 4 | J26: 37795 | K26: UPI | L26: Yes | M26: 3 | N26: Dr. | O26: Mehta
A27: P0026 | B27: Patient_26 | C27: 13 | D27: f | E27: GENERAL MEDICINE | F27: PUNE | G27: 44655 | H27: 44658 | I27: 3 | J27: 67458 | K27: Cash | L27: Yes | M27: 1 | N27: Dr. | O27: Khan
A28: P0027 | B28: Patient_27 | C28: 77 | D28: m | E28: Pediatrics | F28: Pune | G28: 44570 | H28: 14-01-2022 | I28: 5 | J28: 40586 | K28: UPI | L28: No | M28: 4 | N28: Dr. | O28: Mehta
A29: P0028 | B29: Patient_28 | C29: 14 | D29: female | E29: orthopedics | F29: Hyderabad | G29: 31-01-2023 | H29: 44961 | I29: 4 | J29: 143254 | K29: Insurance | L29: Yes | M29: 3 | N29: Dr. | O29: Mehta
A30: P0029 | B30: Patient_29 | C30: 71 | D30: F | E30: cardiology | F30: DELHI | G30: 45261 | H30: 45268 | I30: 7 | J30: 22171 | K30: Cash | L30: Yes | M30: 5 | N30: Dr. | O30: Patil
A31: P0030 | B31: Patient_30 | C31: 3 | D31: male | E31: Pediatrics | F31: Hyderabad | G31: 21-02-2022 | H31: 24-02-2022 | I31: 3 | J31: 43112 | K31: Insurance | L31: No | M31: 1 | N31: Dr. | O31: Desai
A32: P0031 | B32: Patient_31 | C32: 61 | D32: Female | E32: cardiology | F32: mumbai | G32: 17-02-2022 | H32: 22-02-2022 | I32: 5 | J32: 55497 | K32: Card | L32: Yes | M32: 4 | N32: Dr. | O32: Patil
A33: P0032 | B33: Patient_32 | C33: 66 | D33: Female | E33: Neurology | F33: BANGALORE | G33: 17-03-2023 | H33: 18-03-2023 | I33: 1 | J33: 56729 | K33: Insurance | L33: Yes | M33: 2 | N33: Dr. | O33: Sharma
A34: P0033 | B34: Patient_33 | C34: 66 | D34: M | E34: general medicine | F34: pune | G34: 25-03-2023 | H34: 30-03-2023 | I34: 5 | J34: 55844 | K34: Insurance | L34: Yes | M34: 4 | N34: Dr. | O34: Mehta
A35: P0034 | B35: Patient_34 | C35: 73 | D35: M | E35: Cardiology | F35: pune | G35: 13-11-2023 | H35: 15-11-2023 | I35: 2 | J35: 108068 | K35: Cash | L35: Yes | M35: 2 | N35: Dr. | O35: Mehta
A36: P0035 | B36: Patient_35 | C36: 53 | D36: f | E36: General medicine | F36: HYDERABAD | G36: 28-02-2023 | H36: 44991 | I36: 6 | J36: 74279 | K36: Cash | L36: Yes | M36: 2 | N36: Dr. | O36: Desai
A37: P0036 | B37: Patient_36 | C37: 15 | D37: Male | E37: NEUROLOGY | F37: Bangalore | G37: 18-11-2023 | H37: 22-11-2023 | I37: 4 | J37: 134141 | K37: UPI | L37: No | M37: 5 | N37: Dr. | O37: Patil
A38: P0037 | B38: Patient_37 | C38: 22 | D38: Female | E38: Pediatrics | F38: BANGALORE | G38: 22-11-2022 | H38: 24-11-2022 | I38: 2 | J38: 136805 | K38: Cash | L38: No | M38: 2 | N38: Dr. | O38: Sharma
A39: P0038 | B39: Patient_38 | C39: 50 | D39: female | E39: Neurology | F39: HYDERABAD | G39: 14-01-2023 | H39: 16-01-2023 | I39: 2 | J39: 142887 | K39: Cash | L39: No | M39: 2 | N39: Dr. | O39: Khan
A40: P0039 | B40: Patient_39 | C40: 26 | D40: m | E40: General medicine | F40: bangalore | G40: 21-09-2023 | H40: 29-09-2023 | I40: 8 | J40: 17714 | K40: Card | L40: Yes | M40: 2 | N40: Dr. | O40: Khan
...

Sheet Clean data
A1: Patient_ID | B1: Patient_Name | C1: Age | D1: Age_Group | E1: Gender | F1: Department | G1: Doctor_Assigned | H1: City | I1: Admission_Date | J1: Discharge_Date | K1: Length_of_Stay | L1: Treatment_Cost | M1: Cost per day | N1: Cost_Category | O1: Payment_Mode | P1: Insurance_Claimed | Q1: Patient_Satisfaction
A2: P0292 | B2: Patient_292 | C2: 81 | D2: Elderly | E2: Female | F2: Neurology | G2: Dr. Patil | H2: Pune | I2: 45227 | J2: 45237 | K2: =Table3[[#This Row],[Discharge_Date]]-Table3[[#This Row],[Admission_Date]]+1 -> 11 | L2: 5092 | M2: =Table3[[#This Row],[Treatment_Cost]]/Table3[[#This Row],[Length_of_Stay]] -> 462.90909 | N2: =IF(Table3[[#This Row],[Cost per day]]<PERCENTILE(Table3[Cost per day],0.25),"Low", IF(Table3[[#This Row],[Cost per day]]>PERCENTILE(Table3[Cost per day],0.75),"High", "Normal")) -> Low | O2: Insurance | P2: Yes | Q2: 4
A3: P0486 | B3: Patient_486 | C3: 18 | D3: Young Adult | E3: Female | F3: Pediatrics | G3: Dr. Sharma | H3: Hyderabad | I3: 44886 | J3: 44896 | K3: =Table3[[#This Row],[Discharge_Date]]-Table3[[#This Row],[Admission_Date]]+1 -> 11 | L3: 7208 | M3: =Table3[[#This Row],[Treatment_Cost]]/Table3[[#This Row],[Length_of_Stay]] -> 655.27273 | N3: =IF(Table3[[#This Row],[Cost per day]]<PERCENTILE(Table3[Cost per day],0.25),"Low", IF(Table3[[#This Row],[Cost per day]]>PERCENTILE(Table3[Cost per day],0.75),"High", "Normal")) -> Low | O3: Card | P3: Yes | Q3: 1
A4: P0344 | B4: Patient_344 | C4: 33 | D4: Young Adult | E4: Male | F4: Orthopedics | G4: Dr. Khan | H4: Bangalore | I4: 45065 | J4: 45072 | K4: =Table3[[#This Row],[Discharge_Date]]-Table3[[#This Row],[Admission_Date]]+1 -> 8 | L4: 5986 | M4: =Table3[[#This Row],[Treatment_Cost]]/Table3[[#This Row],[Length_of_Stay]] -> 748.25 | N4: =IF(Table3[[#This Row],[Cost per day]]<PERCENTILE(Table3[Cost per day],0.25),"Low", IF(Table3[[#This Row],[Cost per day]]>PERCENTILE(Table3[Cost per day],0.75),"High", "Normal")) -> Low | O4: Insurance | P4: No | Q4: 5
A5: P0190 | B5: Patient_190 | C5: 63 | D5: Senior | E5: Female | F5: Pediatrics | G5: Dr. Mehta | H5: Bangalore | I5: 44644 | J5: 44651 | K5: =Table3[[#This Row],[Discharge_Date]]-Table3[[#This Row],[Admission_Date]]+1 -> 8 | L5: 6033 | M5: =Table3[[#This Row],[Treatment_Cost]]/Table3[[#This Row],[Length_of_Stay]] -> 754.125 | N5: =IF(Table3[[#This Row],[Cost per day]]<PERCENTILE(Table3[Cost per day],0.25),"Low", IF(Table3[[#This Row],[Cost per day]]>PERCENTILE(Table3[Cost per day],0.75),"High", "Normal")) -> Low | O5: Insurance | P5: No | Q5: 1
A6: P0484 | B6: Patient_484 | C6: 39 | D6: Young Adult | E6: Male | F6: Cardiology | G6: Dr. Mehta | H6: Pune | I6: 45249 | J6: 45255 | K6: =Table3[[#This Row],[Discharge_Date]]-Table3[[#This Row],[Admission_Date]]+1 -> 7 | L6: 5818 | M6: =Table3[[#This Row],[Treatment_Cost]]/Table3[[#This Row],[Length_of_Stay]] -> 831.14286 | N6: =IF(Table3[[#This Row],[Cost per day]]<PERCENTILE(Table3[Cost per day],0.25),"Low", IF(Table3[[#This Row],[Cost per day]]>PERCENTILE(Table3[Cost per day],0.75),"High", "Normal")) -> Low | O6: UPI | P6: No | Q6: 1
A7: P0018 | B7: Patient_18 | C7: 68 | D7: Senior | E7: Female | F7: Cardiology | G7: Dr. Mehta | H7: Delhi | I7: 45230 | J7: 45238 | K7: =Table3[[#This Row],[Discharge_Date]]-Table3[[#This Row],[Admission_Date]]+1 -> 9 | L7: 8680 | M7: =Table3[[#This Row],[Treatment_Cost]]/Table3[[#This Row],[Length_of_Stay]] -> 964.44444 | N7: =IF(Table3[[#This Row],[Cost per day]]<PERCENTILE(Table3[Cost per day],0.25),"Low", IF(Table3[[#This Row],[Cost per day]]>PERCENTILE(Table3[Cost per day],0.75),"High", "Normal")) -> Low | O7: Card | P7: No | Q7: 3
A8: P0066 | B8: Patient_66 | C8: 14 | D8: Child | E8: Female | F8: General Medicine | G8: Dr. Patil | H8: Hyderabad | I8: 45293 | J8: 45299 | K8: =Table3[[#This Row],[Discharge_Date]]-Table3[[#This Row],[Admission_Date]]+1 -> 7 | L8: 6769 | M8: =Table3[[#This Row],[Treatment_Cost]]/Table3[[#This Row],[Length_of_Stay]] -> 967 | N8: =IF(Table3[[#This Row],[Cost per day]]<PERCENTILE(Table3[Cost per day],0.25),"Low", IF(Table3[[#This Row],[Cost per day]]>PERCENTILE(Table3[Cost per day],0.75),"High", "Normal")) -> Low | O8: Cash | P8: Yes | Q8: 2
A9: P0448 | B9: Patient_448 | C9: 74 | D9: Senior | E9: Female | F9: Neurology | G9: Dr. Patil | H9: Bangalore | I9: 45292 | J9: 45299 | K9: =Table3[[#This Row],[Discharge_Date]]-Table3[[#This Row],[Admission_Date]]+1 -> 8 | L9: 8107 | M9: =Table3[[#This Row],[Treatment_Cost]]/Table3[[#This Row],[Length_of_Stay]] -> 1013.375 | N9: =IF(Table3[[#This Row],[Cost per day]]<PERCENTILE(Table3[Cost per day],0.25),"Low", IF(Table3[[#This Row],[Cost per day]]>PERCENTILE(Table3[Cost per day],0.75),"High", "Normal")) -> Low | O9: UPI | P9: Yes | Q9: 2
A10: P0255 | B10: Patient_255 | C10: 33 | D10: Young Adult | E10: Female | F10: Orthopedics | G10: Dr. Sharma | H10: Delhi | I10: 45196 | J10: 45205 | K10: =Table3[[#This Row],[Discharge_Date]]-Table3[[#This Row],[Admission_Date]]+1 -> 10 | L10: 10560 | M10: =Table3[[#This Row],[Treatment_Cost]]/Table3[[#This Row],[Length_of_Stay]] -> 1056 | N10: =IF(Table3[[#This Row],[Cost per day]]<PERCENTILE(Table3[Cost per day],0.25),"Low", IF(Table3[[#This Row],[Cost per day]]>PERCENTILE(Table3[Cost per day],0.75),"High", "Normal")) -> Low | O10: Card | P10: Yes | Q10: 1
A11: P0103 | B11: Patient_103 | C11: 15 | D11: Child | E11: Female | F11: Pediatrics | G11: Dr. Mehta | H11: Bangalore | I11: 44955 | J11: 44961 | K11: =Table3[[#This Row],[Discharge_Date]]-Table3[[#This Row],[Admission_Date]]+1 -> 7 | L11: 7066 | M11: =Table3[[#This Row],[Treatment_Cost]]/Table3[[#This Row],[Length_of_Stay]] -> 1009.4286 | N11: =IF(Table3[[#This Row],[Cost per day]]<PERCENTILE(Table3[Cost per day],0.25),"Low", IF(Table3[[#This Row],[Cost per day]]>PERCENTILE(Table3[Cost per day],0.75),"High", "Normal")) -> Low | O11: Cash | P11: No | Q11: 3
A12: P0055 | B12: Patient_55 | C12: 80 | D12: Elderly | E12: Male | F12: General Medicine | G12: Dr. Mehta | H12: Delhi | I12: 45026 | J12: 45036 | K12: =Table3[[#This Row],[Discharge_Date]]-Table3[[#This Row],[Admission_Date]]+1 -> 11 | L12: 12855 | M12: =Table3[[#This Row],[Treatment_Cost]]/Table3[[#This Row],[Length_of_Stay]] -> 1168.6364 | N12: =IF(Table3[[#This Row],[Cost per day]]<PERCENTILE(Table3[Cost per day],0.25),"Low", IF(Table3[[#This Row],[Cost per day]]>PERCENTILE(Table3[Cost per day],0.75),"High", "Normal")) -> Low | O12: Cash | P12: No | Q12: 1
A13: P0087 | B13: Patient_87 | C13: 59 | D13: Middle Age | E13: Male | F13: Cardiology | G13: Dr. Mehta | H13: Pune | I13: 45224 | J13: 45234 | K13: =Table3[[#This Row],[Discharge_Date]]-Table3[[#This Row],[Admission_Date]]+1 -> 11 | L13: 13392 | M13: =Table3[[#This Row],[Treatment_Cost]]/Table3[[#This Row],[Length_of_Stay]] -> 1217.4545 | N13: =IF(Table3[[#This Row],[Cost per day]]<PERCENTILE(Table3[Cost per day],0.25),"Low", IF(Table3[[#This Row],[Cost per day]]>PERCENTILE(Table3[Cost per day],0.75),"High", "Normal")) -> Low | O13: Cash | P13: Yes | Q13: 5
... A501: P0296 | B501: Patient_296 | C501: 76 | D501: Elderly | E501: Female | F501: Pediatrics | G501: Dr. Khan | H501: Mumbai | I501: 44868 | J501: 44869 | K501: =Table3[[#This Row],[Discharge_Date]]-Table3[[#This Row],[Admission_Date]]+1 -> 2 | L501: 149628 | M501: =Table3[[#This Row],[Treatment_Cost]]/Table3[[#This Row],[Length_of_Stay]] -> 74814 | N501: =IF(Table3[[#This Row],[Cost per day]]<PERCENTILE(Table3[Cost per day],0.25),"Low", IF(Table3[[#This Row],[Cost per day]]>PERCENTILE(Table3[Cost per day],0.75),"High", "Normal")) -> High | O501: Cash | P501: No | Q501: 5

Sheet FactDepartment
A1: Date.Date Key | B1: City.1.City Key | C1: Patient.Patient Key | D1: Doctor.Doctor Key | E1: Department | F1: Admission_Date | G1: Discharge_Date | H1: Length_of_Stay | I1: Treatment_Cost | J1: Cost per day | K1: Cost_Category | L1: Column1
A2: 1 | B2: 1 | C2: 1 | D2: 1 | E2: Neurology | F2: 45227 | G2: 45237 | H2: 11 | I2: 5092 | J2: 462.90909 | K2: Low | L2: =VLOOKUP(B2, DimCity!$A:$B, 2, 0) -> #VALUE! | M2: =SUM(Fact_Department[Treatment_Cost]) -> 38153128
A3: 1 | B3: 3 | C3: 66 | D3: 2 | E3: General Medicine | F3: 45227 | G3: 45233 | H3: 7 | I3: 25332 | J3: 3618.8571 | K3: Low | L3: =VLOOKUP(B3, DimCity!$A:$B, 2, 0) -> #VALUE!
A4: 5 | B4: 1 | C4: 5 | D4: 4 | E4: Cardiology | F4: 45249 | G4: 45255 | H4: 7 | I4: 5818 | J4: 831.14286 | K4: Low | L4: =VLOOKUP(B4, DimCity!$A:$B, 2, 0) -> #VALUE!
A5: 2 | B5: 2 | C5: 2 | D5: 2 | E5: Pediatrics | F5: 44886 | G5: 44896 | H5: 11 | I5: 7208 | J5: 655.27273 | K5: Low | L5: =VLOOKUP(B5, DimCity!$A:$B, 2, 0) -> #VALUE!
A6: 2 | B6: 2 | C6: 81 | D6: 2 | E6: General Medicine | F6: 44886 | G6: 44894 | H6: 9 | I6: 44145 | J6: 4905 | K6: Low | L6: =VLOOKUP(B6, DimCity!$A:$B, 2, 0) -> #VALUE!
A7: 3 | B7: 3 | C7: 3 | D7: 3 | E7: Orthopedics | F7: 45065 | G7: 45072 | H7: 8 | I7: 5986 | J7: 748.25 | K7: Low | L7: =VLOOKUP(B7, DimCity!$A:$B, 2, 0) -> #VALUE!
A8: 4 | B8: 3 | C8: 4 | D8: 4 | E8: Pediatrics | F8: 44644 | G8: 44651 | H8: 8 | I8: 6033 | J8: 754.125 | K8: Low | L8: =VLOOKUP(B8, DimCity!$A:$B, 2, 0) -> #VALUE!
A9: 6 | B9: 4 | C9: 6 | D9: 4 | E9: Cardiology | F9: 45230 | G9: 45238 | H9: 9 | I9: 8680 | J9: 964.44444 | K9: Low | L9: =VLOOKUP(B9, DimCity!$A:$B, 2, 0) -> #VALUE!
A10: 7 | B10: 2 | C10: 7 | D10: 1 | E10: General Medicine | F10: 45293 | G10: 45299 | H10: 7 | I10: 6769 | J10: 967 | K10: Low | L10: =VLOOKUP(B10, DimCity!$A:$B, 2, 0) -> #VALUE!
A11: 8 | B11: 3 | C11: 8 | D11: 1 | E11: Neurology | F11: 45292 | G11: 45299 | H11: 8 | I11: 8107 | J11: 1013.375 | K11: Low | L11: =VLOOKUP(B11, DimCity!$A:$B, 2, 0) -> #VALUE!
A12: 9 | B12: 4 | C12: 9 | D12: 2 | E12: Orthopedics | F12: 45196 | G12: 45205 | H12: 10 | I12: 10560 | J12: 1056 | K12: Low | L12: =VLOOKUP(B12, DimCity!$A:$B, 2, 0) -> #VALUE!
A13: 10 | B13: 3 | C13: 10 | D13: 4 | E13: Pediatrics | F13: 44955 | G13: 44961 | H13: 7 | I13: 7066 | J13: 1009.4286 | K13: Low | L13: =VLOOKUP(B13, DimCity!$A:$B, 2, 0) -> #VALUE!
A14: 10 | B14: 2 | C14: 158 | D14: 1 | E14: Orthopedics | F14: 44955 | G14: 44963 | H14: 9 | I14: 83626 | J14: 9291.7778 | K14: Normal | L14: =VLOOKUP(B14, DimCity!$A:$B, 2, 0) -> #VALUE!
... A501: 190 | B501: 5 | C501: 500 | D501: 3 | E501: Pediatrics | F501: 44868 | G501: 44869 | H501: 2 | I501: 149628 | J501: 74814 | K501: High | L501: =VLOOKUP(B501, DimCity!$A:$B, 2, 0) -> #VALUE!

Sheet DimDate
A1: Date Key | B1: Admission_Date | C1: Discharge_Date | D1: Length_of_Stay | E1: Year | F1: Month | G1: Month Name | H1: Quarter
A2: 1 | B2: 45227 | C2: 45237 | D2: 11 | E2: 2023 | F2: 10 | G2: October | H2: 4
A3: 2 | B3: 44886 | C3: 44896 | D3: 11 | E3: 2022 | F3: 11 | G3: November | H3: 4
A4: 3 | B4: 45065 | C4: 45072 | D4: 8 | E4: 2023 | F4: 5 | G4: May | H4: 2
A5: 4 | B5: 44644 | C5: 44651 | D5: 8 | E5: 2022 | F5: 3 | G5: March | H5: 1
A6: 5 | B6: 45249 | C6: 45255 | D6: 7 | E6: 2023 | F6: 11 | G6: November | H6: 4
A7: 6 | B7: 45230 | C7: 45238 | D7: 9 | E7: 2023 | F7: 10 | G7: October | H7: 4
A8: 7 | B8: 45293 | C8: 45299 | D8: 7 | E8: 2024 | F8: 1 | G8: January | H8: 1
A9: 8 | B9: 45292 | C9: 45299 | D9: 8 | E9: 2024 | F9: 1 | G9: January | H9: 1
A10: 9 | B10: 45196 | C10: 45205 | D10: 10 | E10: 2023 | F10: 9 | G10: September | H10: 3
A11: 10 | B11: 44955 | C11: 44961 | D11: 7 | E11: 2023 | F11: 1 | G11: January | H11: 1
A12: 11 | B12: 45026 | C12: 45036 | D12: 11 | E12: 2023 | F12: 4 | G12: April | H12: 2
A13: 12 | B13: 45224 | C13: 45234 | D13: 11 | E13: 2023 | F13: 10 | G13: October | H13: 4
... A394: 393 | B394: 45236 | C394: 45237 | D394: 2 | E394: 2023 | F394: 11 | G394: November | H394: 4

Sheet DimPatient
A1: Patient Key | B1: Patient_ID | C1: Age_Group | D1: Gender | E1: Payment_Mode | F1: Insurance_Claimed | G1: Patient_Satisfaction
A2: 1 | B2: P0292 | C2: Elderly | D2: Female | E2: Insurance | F2: Yes | G2: 4 | K2: =COUNTA(Dim_Patient[Patient_ID]) -> 500
A3: 2 | B3: P0486 | C3: Young Adult | D3: Female | E3: Card | F3: Yes | G3: 1
A4: 3 | B4: P0344 | C4: Young Adult | D4: Male | E4: Insurance | F4: No | G4: 5
A5: 4 | B5: P0190 | C5: Senior | D5: Female | E5: Insurance | F5: No | G5: 1
A6: 5 | B6: P0484 | C6: Young Adult | D6: Male | E6: UPI | F6: No | G6: 1
A7: 6 | B7: P0018 | C7: Senior | D7: Female | E7: Card | F7: No | G7: 3
A8: 7 | B8: P0066 | C8: Child | D8: Female | E8: Cash | F8: Yes | G8: 2
A9: 8 | B9: P0448 | C9: Senior | D9: Female | E9: UPI | F9: Yes | G9: 2
A10: 9 | B10: P0255 | C10: Young Adult | D10: Female | E10: Card | F10: Yes | G10: 1
A11: 10 | B11: P0103 | C11: Child | D11: Female | E11: Cash | F11: No | G11: 3
A12: 11 | B12: P0055 | C12: Elderly | D12: Male | E12: Cash | F12: No | G12: 1
A13: 12 | B13: P0087 | C13: Middle Age | D13: Male | E13: Cash | F13: Yes | G13: 5
A14: 13 | B14: P0171 | C14: Young Adult | D14: Female | E14: Card | F14: Yes | G14: 4
... A501: 500 | B501: P0296 | C501: Elderly | D501: Female | E501: Cash | F501: No | G501: 5

Sheet DimCity
A1: City Key | B1: City | C1: Country/region
A2: 1 | B2: #VALUE! | C2: {=_FV(Dim_City[[#This Row],[City]],"Country/region",TRUE)} -> #VALUE! | H2: =COUNT(Dim_City[City Key]) -> 5
A3: 2 | B3: #VALUE! | C3: #VALUE!
A4: 3 | B4: #VALUE! | C4: #VALUE!
A5: 4 | B5: #VALUE! | C5: #VALUE!
A6: 5 | B6: #VALUE! | C6: {=_FV(Dim_City[[#This Row],[City]],"Country/region",TRUE)} -> #VALUE!

Sheet DimDoctor
A1: Doctor Key | B1: Doctor_Assigned
A2: 1 | B2: Dr. Patil | I2: =COUNT(Dim_Doctor[Doctor Key]) -> 5
A3: 2 | B3: Dr. Sharma
A4: 3 | B4: Dr. Khan
A5: 4 | B5: Dr. Mehta
A6: 5 | B6: Dr. Desai

Sheet pivot table
A1: City | B1: Sum of Treatment_Cost | I1: Sum of Treatment_Cost | J1: City | S1: department | T1: Average of Cost per day | W1: department | X1: Sum of Treatment_Cost | AB1: Sum of Treatment_Cost | AC1: Year | AG1: Dep | AH1: Count of Patient Key
A2: Delhi | B2: 6277519 | I2: Department | J2: Bangalore | K2: Delhi | L2: Hyderabad | M2: Mumbai | N2: Pune | S2: Cardiology | T2: 14448.511 | W2: Cardiology | X2: 6333532 | AB2: Dep | AC2: 2022 | AD2: 2023 | AE2: 2024 | AG2: Orthopedics | AH2: 87
A3: Pune | B3: 7093413 | I3: Cardiology | J3: 1624004 | K3: 799313 | L3: 1647935 | M3: 819859 | N3: 1442421 | O3: =COUNTA(I3:I7) -> 5 | S3: General Medicine | T3: 15491.323 | W3: Orthopedics | X3: 6697077 | AB3: Cardiology | AC3: 3153286 | AD3: 2747134 | AE3: 433112 | AG3: Cardiology | AH3: 91
A4: Mumbai | B4: 7397370 | I4: General Medicine | J4: 1708728 | K4: 1250219 | L4: 1668785 | M4: 1494318 | N4: 1532266 | S4: Pediatrics | T4: 16026.137 | W4: General Medicine | X4: 7654316 | AB4: Orthopedics | AC4: 2535286 | AD4: 2862287 | AE4: 1299504 | AG4: General Medicine | AH4: 104
A5: Bangalore | B5: 8193371 | I5: Neurology | J5: 2309275 | K5: 1220044 | L5: 3022486 | M5: 1617394 | N5: 1438765 | S5: Orthopedics | T5: 16995.851 | W5: Pediatrics | X5: 7860239 | AB5: General Medicine | AC5: 3104610 | AD5: 2925922 | AE5: 1623784 | AG5: Pediatrics | AH5: 106
A6: Hyderabad | B6: 9191455 | I6: Orthopedics | J6: 930729 | K6: 1385973 | L6: 1834597 | M6: 1790015 | N6: 755763 | S6: Neurology | T6: 18896.264 | W6: Neurology | X6: 9607964 | AB6: Pediatrics | AC6: 3606874 | AD6: 2988929 | AE6: 1264436 | AG6: Neurology | AH6: 112
A7: Grand Total | B7: 38153128 | I7: Pediatrics | J7: 1620635 | K7: 1621970 | L7: 1017652 | M7: 1675784 | N7: 1924198 | AB7: Neurology | AC7: 4047152 | AD7: 3980767 | AE7: 1580045
A16: City | B16: Average of Cost per day
A17: Pune | B17: 14897.561
A18: Bangalore | B18: 15334.911
A19: Delhi | B19: 16754.177
A20: Mumbai | B20: 17416.462 | I20: Sum of Treatment_Cost | J20: Doctor
A21: Hyderabad | B21: 17706.523 | I21: City | J21: Dr. Desai | K21: Dr. Khan | L21: Dr. Mehta | M21: Dr. Patil | N21: Dr. Sharma
I22: Bangalore | J22: 1124861 | K22: 1826358 | L22: 2545374 | M22: 1548607 | N22: 1148171 | U22: Average of Cost per day | V22: Department
I23: Delhi | J23: 1227090 | K23: 595165 | L23: 1918159 | M23: 1181524 | N23: 1355581 | U23: Doctor | V23: Cardiology | W23: General Medicine | X23: Neurology | Y23: Orthopedics | Z23: Pediatrics
I24: Hyderabad | J24: 1557632 | K24: 1737255 | L24: 2460054 | M24: 1063919 | N24: 2372595 | U24: Dr. Desai | V24: 18393.921 | W24: 16658.592 | X24: 22576.762 | Y24: 20969.31 | Z24: 13819.515
I25: Mumbai | J25: 1760936 | K25: 1750044 | L25: 1435297 | M25: 814284 | N25: 1636809 | U25: Dr. Khan | V25: 13698.58 | W25: 16436.386 | X25: 24010.607 | Y25: 17629.355 | Z25: 20804.78
I26: Pune | J26: 2086039 | K26: 1448563 | L26: 1260487 | M26: 899216 | N26: 1399108 | U26: Dr. Mehta | V26: 12146.997 | W26: 13765.603 | X26: 16942.547 | Y26: 14272.436 | Z26: 12956.621
U27: Dr. Patil | V27: 11598.747 | W27: 13990.59 | X27: 16038.304 | Y27: 11757.032 | Z27: 14666.063
U28: Dr. Sharma | V28: 17786.971 | W28: 16766.823 | X28: 16733.798 | Y28: 19514.588 | Z28: 16685.331
A29: City | B29: Count of Patient Key
A30: Delhi | B30: 80
A31: Mumbai | B31: 91
A32: Pune | B32: 97
A33: Bangalore | B33: 109
A34: Hyderabad | B34: 123
A43: Sum of Treatment_Cost | B43: Year
A44: City | B44: 2022 | C44: 2023 | D44: 2024 | U44: doctor | V44: Sum of Treatment_Cost | Y44: doctor | Z44: Average of Cost per day
A45: Bangalore | B45: 4628857 | C45: 2528338 | D45: 1036176 | U45: Dr. Patil | V45: 5507550 | Y45: Cardiology | Z45: 14448.511
A46: Delhi | B46: 1835062 | C46: 3260716 | D46: 1181741 | U46: Dr. Khan | V46: 7357385 | Y46: General Medicine | Z46: 15491.323
A47: Hyderabad | B47: 3589295 | C47: 4184249 | D47: 1417911 | U47: Dr. Desai | V47: 7756558 | Y47: Pediatrics | Z47: 16026.137
A48: Mumbai | B48: 3490267 | C48: 2618227 | D48: 1288876 | U48: Dr. Sharma | V48: 7912264 | Y48: Orthopedics | Z48: 16995.851
A49: Pune | B49: 2903727 | C49: 2913509 | D49: 1276177 | U49: Dr. Mehta | V49: 9619371 | Y49: Neurology | Z49: 18896.264
A80: Age Grp | B80: Sum of Treatment_Cost | J80: Year | K80: Sum of Treatment_Cost
A81: Elderly | B81: 6138983 | J81: 2022 | S81: Gender | T81: Count of Patient Key | X81: Average of Length_of_Stay
A82: Senior | B82: 7033776 | J82: Qtr1 | K82: 4122912 | S82: Female | T82: 258 | X82: 6.088
A83: Child | B83: 7641623 | J83: Qtr2 | K83: 4053213 | S83: Male | T83: 242
A84: Middle Age | B84: 8441402 | J84: Qtr3 | K84: 4172890
A85: Young Adult | B85: 8897344 | J85: Qtr4 | K85: 4098193
J86: 2023
...

Sheet Department Dashboard

Sheet City Dashboard
